Workbook

Sheet Read Me
A1: Amped Up Network Financial Model
A3: How to use | B3: Edit yellow cells only. Assumptions controls recurring cost and price drivers; yellow rows on 12 Month Cash Flow control launch timing, one-time payment timing, and outside funding/debt/investment draws. Vendor campaign contributions are modeled as revenue and their incremental delivery cost is modeled separately. Formula rows recalculate automatically when opened in Excel, Numbers, or Google Sheets.
A5: Backloading | B5: Set each recurring expense start month on Assumptions. Move legal, equipment, and other one-time payments across the yellow schedule on 12 Month Cash Flow. Completed bookings are calculated from active Certified Partners after the configurable qualification delay, using the trailing booking window on Assumptions. Use the yellow External funding draw row only when a loan, investment, or founder contribution is expected to close; do not count an uncommitted source as cash.
A7: Capital decision | B7: Funding calculates the reserve requirement from the lowest cash point before funding. It shows the difference between minimum required funding and the timing of a proposed draw. All figures are planning assumptions, not financial advice or an earnings claim.

Sheet Assumptions
A1: Editable Assumptions
A3: Driver | B3: Value | C3: Units | D3: Notes
A4: Founder / operations monthly cash cost | B4: 4000 | C4: per month | D4: Founder-led draw and targeted operating support; excludes replacement-value labor.
A5: Founder / operations start month | B5: 4 | C5: month number | D5: Delay draw until the business reaches the chosen milestone; do not defer necessary safety/compliance work.
A6: Engineering / product monthly cash cost | B6: 2000 | C6: per month | D6: Contract only milestone-critical work.
A7: Engineering / product start month | B7: 2 | C7: month number
A8: Content / social monthly cash cost | B8: 1500 | C8: per month | D8: Family-assisted production plus targeted outside work.
A9: Content / social start month | B9: 3 | C9: month number
A10: Software / payments / data monthly cost | B10: 1500 | C10: per month | D10: Hosting, communications, analytics, CRM, and payment tooling.
A11: Software / payments / data start month | B11: 1 | C11: month number
A12: Marketing / event monthly cash cost | B12: 1500 | C12: per month | D12: Partner-hosted and co-funded events; no self-funded large shows in year one.
A13: Marketing / event start month | B13: 4 | C13: month number
A14: Premises branding / place-based media monthly cost | B14: 1250 | C14: per month | D14: Partner kits and small local media tests before billboards.
A15: Premises branding / place-based media start month | B15: 4 | C15: month number
A16: Connected Garage monthly pilot cost | B16: 1000 | C16: per month | D16: Tesla-first Tessie pilot, secure telemetry storage/processing, and support.
A17: Connected Garage pilot start month | B17: 7 | C17: month number | D17: Set to 13 to defer beyond the first year.
A18: Working-capital reserve | B18: 25000 | C18: cash balance | D18: Minimum desired cash balance, not an operating expense.
A19: Full repair-partner launch fee | B19: 4000 | C19: per partner | D19: Core EV Repair launch program.
A20: Specialty / infrastructure launch fee | B20: 1500 | C20: per partner | D20: Streamlined specialty or infrastructure launch.
A21: Certified Partner monthly membership | B21: 499 | C21: per partner/month
A22: Specialty / infrastructure monthly membership | B22: 199 | C22: per partner/month
A23: Annual member dues | B23: 99 | C23: per new member | D23: Collected upfront in this model.
A24: Completed-booking fee | B24: 40 | C24: per completed booking | D24: Subject to final legal and attribution review.
A25: Vendor / campaign contribution | B25: 3000 | C25: per campaign | D25: Vendor-funded or local partner campaign.
A26: Starting founder capital | B26: 0 | C26: cash | D26: Cash already available before Month 1. Keep at zero when modeling a fully backloaded draw.
A27: Managed-service contribution margin | B27: 0 | C27: per month | D27: Enter only after a bounded service is proven.
A28: Expert-work contribution margin | B28: 0 | C28: per month | D28: Enter only after pricing, payout, tax, and dispute operations are live.
A31: Booking measurement window | B31: 2 | C31: months | D31: Use a trailing two-month window for qualified Certified Partner booking performance.
A32: Completed bookings per qualified Certified Partner / window | B32: 12 | C32: bookings | D32: Total attributable completed bookings expected from each qualified Certified Partner over the measurement window.
A33: Certified Partner booking qualification delay | B33: 2 | C33: months | D33: Months from a partner becoming active before it contributes to booking expectations.
A34: Vendor / local campaign delivery cost | B34: 3500 | C34: per campaign | D34: Total incremental campaign cost: activation staff, permits, media, production, partner materials, and event delivery. Vendor contribution is modeled separately as revenue.

Sheet 12 Month Cash Flow
A1: 12-Month Founder-Led Cash Burn-Down
A2: Yellow cells are timing or funding inputs. All other monthly values are formulas.
A4: Driver / Cash Flow | B4: Month 1 | C4: Month 2 | D4: Month 3 | E4: Month 4 | F4: Month 5 | G4: Month 6 | H4: Month 7 | I4: Month 8 | J4: Month 9 | K4: Month 10 | L4: Month 11 | M4: Month 12
A5: Full repair-partner launches | B5: 0 | C5: 3 | D5: 2 | E5: 2 | F5: 1 | G5: 1 | H5: 1 | I5: 0 | J5: 0 | K5: 0 | L5: 0 | M5: 0
A6: Specialty / infrastructure launches | B6: 0 | C6: 0 | D6: 1 | E6: 1 | F6: 1 | G6: 1 | H6: 1 | I6: 0 | J6: 0 | K6: 0 | L6: 0 | M6: 0
A7: Active Certified Partners | B7: 0 | C7: 0 | D7: 0 | E7: 2 | F7: 4 | G7: 6 | H7: 8 | I7: 10 | J7: 10 | K7: 10 | L7: 10 | M7: 10
A8: Active Specialty / Infrastructure Partners | B8: 0 | C8: 0 | D8: 0 | E8: 2 | F8: 3 | G8: 4 | H8: 5 | I8: 5 | J8: 5 | K8: 5 | L8: 5 | M8: 5
A9: New annual members | B9: 0 | C9: 0 | D9: 25 | E9: 25 | F9: 30 | G9: 40 | H9: 50 | I9: 50 | J9: 50 | K9: 50 | L9: 40 | M9: 40
A10: Completed attributable bookings (formula) | B10: =IF(COLUMN()-1<=Assumptions!$B$33,0,INDEX($B$7:$M$7,1,COLUMN()-1-Assumptions!$B$33)*Assumptions!$B$32/Assumptions!$B$31) | C10: =IF(COLUMN()-1<=Assumptions!$B$33,0,INDEX($B$7:$M$7,1,COLUMN()-1-Assumptions!$B$33)*Assumptions!$B$32/Assumptions!$B$31) | D10: =IF(COLUMN()-1<=Assumptions!$B$33,0,INDEX($B$7:$M$7,1,COLUMN()-1-Assumptions!$B$33)*Assumptions!$B$32/Assumptions!$B$31) | E10: =IF(COLUMN()-1<=Assumptions!$B$33,0,INDEX($B$7:$M$7,1,COLUMN()-1-Assumptions!$B$33)*Assumptions!$B$32/Assumptions!$B$31) | F10: =IF(COLUMN()-1<=Assumptions!$B$33,0,INDEX($B$7:$M$7,1,COLUMN()-1-Assumptions!$B$33)*Assumptions!$B$32/Assumptions!$B$31) | G10: =IF(COLUMN()-1<=Assumptions!$B$33,0,INDEX($B$7:$M$7,1,COLUMN()-1-Assumptions!$B$33)*Assumptions!$B$32/Assumptions!$B$31) | H10: =IF(COLUMN()-1<=Assumptions!$B$33,0,INDEX($B$7:$M$7,1,COLUMN()-1-Assumptions!$B$33)*Assumptions!$B$32/Assumptions!$B$31) | I10: =IF(COLUMN()-1<=Assumptions!$B$33,0,INDEX($B$7:$M$7,1,COLUMN()-1-Assumptions!$B$33)*Assumptions!$B$32/Assumptions!$B$31) | ... M10: =IF(COLUMN()-1<=Assumptions!$B$33,0,INDEX($B$7:$M$7,1,COLUMN()-1-Assumptions!$B$33)*Assumptions!$B$32/Assumptions!$B$31)
A11: Vendor / local campaigns | B11: 0 | C11: 0 | D11: 0 | E11: 0 | F11: 0 | G11: 1 | H11: 0 | I11: 0 | J11: 0 | K11: 1 | L11: 0 | M11: 0
A12: Legal / compliance payment schedule | B12: 0 | C12: 0 | D12: 4000 | E12: 6000 | F12: 8000 | G12: 8000 | H12: 2000 | I12: 0 | J12: 2000 | K12: 0 | L12: 0 | M12: 0
A13: Equipment / initial production payment schedule | B13: 0 | C13: 0 | D13: 0 | E13: 0 | F13: 5000 | G13: 5000 | H13: 0 | I13: 0 | J13: 0 | K13: 0 | L13: 0 | M13: 0
A14: External funding draw: debt / investment / founder | B14: 0 | C14: 0 | D14: 0 | E14: 0 | F14: 0 | G14: 0 | H14: 0 | I14: 0 | J14: 0 | K14: 0 | L14: 0 | M14: 0
A16: Revenue
A17: Full partner-launch fees | B17: =B5*Assumptions!$B$19 | C17: =C5*Assumptions!$B$19 | D17: =D5*Assumptions!$B$19 | E17: =E5*Assumptions!$B$19 | F17: =F5*Assumptions!$B$19 | G17: =G5*Assumptions!$B$19 | H17: =H5*Assumptions!$B$19 | I17: =I5*Assumptions!$B$19 | ... M17: =M5*Assumptions!$B$19
A18: Specialty/infrastructure launch fees | B18: =B6*Assumptions!$B$20 | C18: =C6*Assumptions!$B$20 | D18: =D6*Assumptions!$B$20 | E18: =E6*Assumptions!$B$20 | F18: =F6*Assumptions!$B$20 | G18: =G6*Assumptions!$B$20 | H18: =H6*Assumptions!$B$20 | I18: =I6*Assumptions!$B$20 | ... M18: =M6*Assumptions!$B$20
A19: Certified Partner memberships | B19: =B7*Assumptions!$B$21 | C19: =C7*Assumptions!$B$21 | D19: =D7*Assumptions!$B$21 | E19: =E7*Assumptions!$B$21 | F19: =F7*Assumptions!$B$21 | G19: =G7*Assumptions!$B$21 | H19: =H7*Assumptions!$B$21 | I19: =I7*Assumptions!$B$21 | ... M19: =M7*Assumptions!$B$21
A20: Specialty/infrastructure memberships | B20: =B8*Assumptions!$B$22 | C20: =C8*Assumptions!$B$22 | D20: =D8*Assumptions!$B$22 | E20: =E8*Assumptions!$B$22 | F20: =F8*Assumptions!$B$22 | G20: =G8*Assumptions!$B$22 | H20: =H8*Assumptions!$B$22 | I20: =I8*Assumptions!$B$22 | ... M20: =M8*Assumptions!$B$22
A21: Annual consumer memberships | B21: =B9*Assumptions!$B$23 | C21: =C9*Assumptions!$B$23 | D21: =D9*Assumptions!$B$23 | E21: =E9*Assumptions!$B$23 | F21: =F9*Assumptions!$B$23 | G21: =G9*Assumptions!$B$23 | H21: =H9*Assumptions!$B$23 | I21: =I9*Assumptions!$B$23 | ... M21: =M9*Assumptions!$B$23
A22: Completed-booking fees | B22: =B10*Assumptions!$B$24 | C22: =C10*Assumptions!$B$24 | D22: =D10*Assumptions!$B$24 | E22: =E10*Assumptions!$B$24 | F22: =F10*Assumptions!$B$24 | G22: =G10*Assumptions!$B$24 | H22: =H10*Assumptions!$B$24 | I22: =I10*Assumptions!$B$24 | ... M22: =M10*Assumptions!$B$24
A23: Vendor / campaign contributions | B23: =B11*Assumptions!$B$25 | C23: =C11*Assumptions!$B$25 | D23: =D11*Assumptions!$B$25 | E23: =E11*Assumptions!$B$25 | F23: =F11*Assumptions!$B$25 | G23: =G11*Assumptions!$B$25 | H23: =H11*Assumptions!$B$25 | I23: =I11*Assumptions!$B$25 | ... M23: =M11*Assumptions!$B$25
A24: Managed-service contribution | B24: =Assumptions!$B$28 | C24: =Assumptions!$B$28 | D24: =Assumptions!$B$28 | E24: =Assumptions!$B$28 | F24: =Assumptions!$B$28 | G24: =Assumptions!$B$28 | H24: =Assumptions!$B$28 | I24: =Assumptions!$B$28 | ... M24: =Assumptions!$B$28
A25: Expert-work contribution | B25: =Assumptions!$B$29 | C25: =Assumptions!$B$29 | D25: =Assumptions!$B$29 | E25: =Assumptions!$B$29 | F25: =Assumptions!$B$29 | G25: =Assumptions!$B$29 | H25: =Assumptions!$B$29 | I25: =Assumptions!$B$29 | ... M25: =Assumptions!$B$29
A26: Total revenue | B26: =SUM(B17:B25) | C26: =SUM(C17:C25) | D26: =SUM(D17:D25) | E26: =SUM(E17:E25) | F26: =SUM(F17:F25) | G26: =SUM(G17:G25) | H26: =SUM(H17:H25) | I26: =SUM(I17:I25) | ... M26: =SUM(M17:M25)
A28: Cash operating expenses
A29: Founder / operations | B29: =IF(COLUMN()-1>=Assumptions!$B$5,Assumptions!$B$4,0) | C29: =IF(COLUMN()-1>=Assumptions!$B$5,Assumptions!$B$4,0) | D29: =IF(COLUMN()-1>=Assumptions!$B$5,Assumptions!$B$4,0) | E29: =IF(COLUMN()-1>=Assumptions!$B$5,Assumptions!$B$4,0) | F29: =IF(COLUMN()-1>=Assumptions!$B$5,Assumptions!$B$4,0) | G29: =IF(COLUMN()-1>=Assumptions!$B$5,Assumptions!$B$4,0) | H29: =IF(COLUMN()-1>=Assumptions!$B$5,Assumptions!$B$4,0) | I29: =IF(COLUMN()-1>=Assumptions!$B$5,Assumptions!$B$4,0) | ... M29: =IF(COLUMN()-1>=Assumptions!$B$5,Assumptions!$B$4,0)
A30: Engineering / product | B30: =IF(COLUMN()-1>=Assumptions!$B$7,Assumptions!$B$6,0) | C30: =IF(COLUMN()-1>=Assumptions!$B$7,Assumptions!$B$6,0) | D30: =IF(COLUMN()-1>=Assumptions!$B$7,Assumptions!$B$6,0) | E30: =IF(COLUMN()-1>=Assumptions!$B$7,Assumptions!$B$6,0) | F30: =IF(COLUMN()-1>=Assumptions!$B$7,Assumptions!$B$6,0) | G30: =IF(COLUMN()-1>=Assumptions!$B$7,Assumptions!$B$6,0) | H30: =IF(COLUMN()-1>=Assumptions!$B$7,Assumptions!$B$6,0) | I30: =IF(COLUMN()-1>=Assumptions!$B$7,Assumptions!$B$6,0) | ... M30: =IF(COLUMN()-1>=Assumptions!$B$7,Assumptions!$B$6,0)
A31: Content / social | B31: =IF(COLUMN()-1>=Assumptions!$B$9,Assumptions!$B$8,0) | C31: =IF(COLUMN()-1>=Assumptions!$B$9,Assumptions!$B$8,0) | D31: =IF(COLUMN()-1>=Assumptions!$B$9,Assumptions!$B$8,0) | E31: =IF(COLUMN()-1>=Assumptions!$B$9,Assumptions!$B$8,0) | F31: =IF(COLUMN()-1>=Assumptions!$B$9,Assumptions!$B$8,0) | G31: =IF(COLUMN()-1>=Assumptions!$B$9,Assumptions!$B$8,0) | H31: =IF(COLUMN()-1>=Assumptions!$B$9,Assumptions!$B$8,0) | I31: =IF(COLUMN()-1>=Assumptions!$B$9,Assumptions!$B$8,0) | ... M31: =IF(COLUMN()-1>=Assumptions!$B$9,Assumptions!$B$8,0)
A32: Software / payments / data | B32: =IF(COLUMN()-1>=Assumptions!$B$11,Assumptions!$B$10,0) | C32: =IF(COLUMN()-1>=Assumptions!$B$11,Assumptions!$B$10,0) | D32: =IF(COLUMN()-1>=Assumptions!$B$11,Assumptions!$B$10,0) | E32: =IF(COLUMN()-1>=Assumptions!$B$11,Assumptions!$B$10,0) | F32: =IF(COLUMN()-1>=Assumptions!$B$11,Assumptions!$B$10,0) | G32: =IF(COLUMN()-1>=Assumptions!$B$11,Assumptions!$B$10,0) | H32: =IF(COLUMN()-1>=Assumptions!$B$11,Assumptions!$B$10,0) | I32: =IF(COLUMN()-1>=Assumptions!$B$11,Assumptions!$B$10,0) | ... M32: =IF(COLUMN()-1>=Assumptions!$B$11,Assumptions!$B$10,0)
A33: Marketing / events | B33: =IF(COLUMN()-1>=Assumptions!$B$13,Assumptions!$B$12,0) | C33: =IF(COLUMN()-1>=Assumptions!$B$13,Assumptions!$B$12,0) | D33: =IF(COLUMN()-1>=Assumptions!$B$13,Assumptions!$B$12,0) | E33: =IF(COLUMN()-1>=Assumptions!$B$13,Assumptions!$B$12,0) | F33: =IF(COLUMN()-1>=Assumptions!$B$13,Assumptions!$B$12,0) | G33: =IF(COLUMN()-1>=Assumptions!$B$13,Assumptions!$B$12,0) | H33: =IF(COLUMN()-1>=Assumptions!$B$13,Assumptions!$B$12,0) | I33: =IF(COLUMN()-1>=Assumptions!$B$13,Assumptions!$B$12,0) | ... M33: =IF(COLUMN()-1>=Assumptions!$B$13,Assumptions!$B$12,0)
A34: Premises branding / place-based media | B34: =IF(COLUMN()-1>=Assumptions!$B$15,Assumptions!$B$14,0) | C34: =IF(COLUMN()-1>=Assumptions!$B$15,Assumptions!$B$14,0) | D34: =IF(COLUMN()-1>=Assumptions!$B$15,Assumptions!$B$14,0) | E34: =IF(COLUMN()-1>=Assumptions!$B$15,Assumptions!$B$14,0) | F34: =IF(COLUMN()-1>=Assumptions!$B$15,Assumptions!$B$14,0) | G34: =IF(COLUMN()-1>=Assumptions!$B$15,Assumptions!$B$14,0) | H34: =IF(COLUMN()-1>=Assumptions!$B$15,Assumptions!$B$14,0) | I34: =IF(COLUMN()-1>=Assumptions!$B$15,Assumptions!$B$14,0) | ... M34: =IF(COLUMN()-1>=Assumptions!$B$15,Assumptions!$B$14,0)
A35: Connected Garage pilot | B35: =IF(COLUMN()-1>=Assumptions!$B$17,Assumptions!$B$16,0) | C35: =IF(COLUMN()-1>=Assumptions!$B$17,Assumptions!$B$16,0) | D35: =IF(COLUMN()-1>=Assumptions!$B$17,Assumptions!$B$16,0) | E35: =IF(COLUMN()-1>=Assumptions!$B$17,Assumptions!$B$16,0) | F35: =IF(COLUMN()-1>=Assumptions!$B$17,Assumptions!$B$16,0) | G35: =IF(COLUMN()-1>=Assumptions!$B$17,Assumptions!$B$16,0) | H35: =IF(COLUMN()-1>=Assumptions!$B$17,Assumptions!$B$16,0) | I35: =IF(COLUMN()-1>=Assumptions!$B$17,Assumptions!$B$16,0) | ... M35: =IF(COLUMN()-1>=Assumptions!$B$17,Assumptions!$B$16,0)
A36: Legal / compliance | B36: =B12 | C36: =C12 | D36: =D12 | E36: =E12 | F36: =F12 | G36: =G12 | H36: =H12 | I36: =I12 | ... M36: =M12
A37: Equipment / initial production | B37: =B13 | C37: =C13 | D37: =D13 | E37: =E13 | F37: =F13 | G37: =G13 | H37: =H13 | I37: =I13 | ... M37: =M13
A38: Vendor / local campaign delivery cost | B38: =B11*Assumptions!$B$34 | C38: =C11*Assumptions!$B$34 | D38: =D11*Assumptions!$B$34 | E38: =E11*Assumptions!$B$34 | F38: =F11*Assumptions!$B$34 | G38: =G11*Assumptions!$B$34 | H38: =H11*Assumptions!$B$34 | I38: =I11*Assumptions!$B$34 | ... M38: =M11*Assumptions!$B$34
A39: Total operating expenses | B39: =SUM(B29:B38) | C39: =SUM(C29:C38) | D39: =SUM(D29:D38) | E39: =SUM(E29:E38) | F39: =SUM(F29:F38) | G39: =SUM(G29:G38) | H39: =SUM(H29:H38) | I39: =SUM(I29:I38) | ... M39: =SUM(M29:M38)
A41: Cash position
A42: Net operating cash flow | B42: =B26-B39 | C42: =C26-C39 | D42: =D26-D39 | E42: =E26-E39 | F42: =F26-F39 | G42: =G26-G39 | H42: =H26-H39 | I42: =I26-I39 | ... M42: =M26-M39
A43: Cumulative cash before funding | B43: =B42 | C43: =B43+C42 | D43: =C43+D42 | E43: =D43+E42 | F43: =E43+F42 | G43: =F43+G42 | H43: =G43+H42 | I43: =H43+I42 | J43: =I43+J42 | ... M43: =L43+M42
A44: Opening cash | B44: =Assumptions!$B$27 | C44: =B46 | D44: =C46 | E44: =D46 | F44: =E46 | G44: =F46 | H44: =G46 | I44: =H46 | J44: =I46 | ... M44: =L46
...

Sheet Funding
A1: Funding Waterfall and Capital Timing
A3: Measure | B3: Formula / Value | C3: Interpretation
A4: Launch-year revenue receipts | B4: =SUM('12 Month Cash Flow'!B26:M26) | C4: Cash receipts from the launch schedule, recurring memberships, annual dues, booking fees, and campaign contributions.
A5: Launch-year operating expenses | B5: =SUM('12 Month Cash Flow'!B39:M39) | C5: Cash operating costs, including the editable legal and equipment schedules.
A6: Launch-year net operating cash flow | B6: =B4-B5 | C6: Negative means the ramp consumes cash before founder or external funding.
A7: Lowest cumulative cash before funding | B7: =MIN('12 Month Cash Flow'!B43:M43) | C7: Worst point if no starting capital or external funding is drawn.
A8: Required reserve | B8: =Assumptions!$B$18 | C8: Minimum desired balance.
A9: Minimum funding to preserve reserve | B9: =MAX(0,-B7+B8) | C9: Capital required in total, regardless of whether it is founder capital, debt, or investment.
A10: Recommended 10% contingency | B10: =B9*10% | C10: Delay/refund/collection-risk buffer.
A11: Recommended total committed capital | B11: =B9+B10 | C11: Capital that should be committed or contractually available before launch.
A12: Scheduled starting capital and external draws | B12: =Assumptions!$B$27+SUM('12 Month Cash Flow'!B45:M45) | C12: Only enter funded or formally committed sources.
A13: Committed capital surplus / (shortfall) | B13: =B12-B11 | C13: Positive means the plan meets the target; negative means reduce burn, accelerate receipts, or close funding.
A16: Funding order
A17: 1. Partner launch fees and annual member dues | B17: First | C17: Collect launch fees in milestone-based installments and annual membership revenue upfront where possible.
A18: 2. Delayable founder draw and staged initial payments | B18: Cash preservation | C18: Use start-month controls and payment schedules to align cash cost with actual partner/member activation, not with a calendar date.
A19: 3. Founder capital or committed outside investment | B19: Base-case gap | C19: Fund the calculated reserve requirement and legal/product milestones. Draw later only if the source is committed before the cash trough.
A20: 4. Small working-capital line | B20: Contingency | C20: Use only for contracted timing gaps after recurring collections exist; do not rely on debt for speculative events or open-ended payroll.
A21: 5. Strategic/equity investment | B21: Expansion | C21: Use for multi-market expansion, a facility, accelerated Connected Garage development, or a staffed team.

Sheet Mature Run Rate
A1: Mature First-Market Annual Run Rate
A3: Driver / Revenue line | B3: Formula / Value | C3: Notes
A4: Certified Partners | B4: 10 | C4: Editable operating target.
A5: Specialty / Infrastructure Partners | B5: 5 | C5: Editable operating target.
A6: Full repair launches per year | B6: 10 | C6: New full launches after initial market activation.
A7: Specialty / infrastructure launches per year | B7: 5 | C7: New lighter launches after initial market activation.
A8: Annual consumer members | B8: 400 | C8: At annual member dues in the base case.
A9: Completed bookings / qualified Certified Partner / window | B9: =Assumptions!$B$32 | C9: Formula uses the booking-window and qualification-delay assumptions on Assumptions.
A10: Vendor / local campaigns per year | B10: 4 | C10: At the Assumptions campaign contribution.
A12: Revenue
A13: Full partner launches | B13: =B6*Assumptions!$B$19 | C13: Formula driven by the editable target above and Assumptions.
A14: Specialty/infrastructure launches | B14: =B7*Assumptions!$B$20 | C14: Formula driven by the editable target above and Assumptions.
A15: Certified Partner memberships | B15: =B4*Assumptions!$B$21*12 | C15: Formula driven by the editable target above and Assumptions.
A16: Specialty/infrastructure memberships | B16: =B5*Assumptions!$B$22*12 | C16: Formula driven by the editable target above and Assumptions.
A17: Annual consumer memberships | B17: =B8*Assumptions!$B$23 | C17: Formula driven by the editable target above and Assumptions.
A18: Completed-booking fees | B18: =B4*B9/Assumptions!$B$31*12*Assumptions!$B$24 | C18: Certified Partners x bookings per trailing window / window months x 12 x completed-booking fee.
A19: Vendor/local campaigns | B19: =B10*Assumptions!$B$25 | C19: Formula driven by the editable target above and Assumptions.
A20: Managed-service contribution | B20: =Assumptions!$B$28*12 | C20: Formula driven by the editable target above and Assumptions.
A21: Expert-work contribution | B21: =Assumptions!$B$29*12 | C21: Formula driven by the editable target above and Assumptions.
A22: Total annual gross revenue | B22: =SUM(B13:B21) | C22: Gross revenue only. Add direct costs, staffing, taxes, payment fees, refunds, and market-specific overhead before using this as a profitability estimate.
